Workbook

Sheet Résumé de l’exportation
B3: Ce document a été exporté depuis Numbers. Chaque tableau a été converti en feuille de calcul Excel. Tous les autres objets sur chaque feuille Numbers ont été placés sur des feuilles de calcul différentes. Veuillez noter que les calculs de formules peuvent être différents dans Excel.
B7: Nom de la feuille Numbers | C7: Nom du tableau Numbers | D7: Nom de la feuille de calcul Excel
B9: SAMPLE - Monthly Profit & Loss
C10: Table 1 | D10: SAMPLE - Monthly Profit & Loss
B11: SAMPLE - Monthly Profit & Loss-1
C12: Table 1 | D12: SAMPLE - Monthly Profit & Loss-
B13: SAMPLE - Profit & Loss YTD
C14: Table 1 | D14: SAMPLE - Profit & Loss YTD - Ta
B15: BLANK - Monthly Profit & Loss
C16: Table 1 | D16: BLANK - Monthly Profit & Loss -
B17: BLANK - Profit & Loss YTD
C18: Table 1 | D18: BLANK - Profit & Loss YTD - Tab

Sheet SAMPLE - Monthly Profit & Loss 
B1: MONTHLY PROFIT AND LOSS
B2: COMPANY NAME
B3: Hackboot
B5: Last Update and verification
B6: 45984
C8: TREND | D8: JANUARY | E8: FEBRUARY | F8: MARCH | G8: APRIL | H8: MAY | I8: JUNE | J8: JULY | K8: AUGUST | L8: SEPTEMBER | M8: OCTOBER | N8: NOVEMBER | O8: DECEMBER | Q8: YTD
B9: GROSS PROFIT | D9: {=D39} -> 18640.8 | E9: {=E39} -> 12440.4 | F9: {=F39} -> 22052.4 | G9: {=G39} -> 26091.6 | H9: {=H39} -> 12633.2 | I9: {=I39} -> 25394.4 | J9: {=J39} -> 0 | K9: {=K39} -> 0 | ... O9: {=O39} -> 7408.68 | Q9: {=SUM(D9:O9)} -> 131824.98
B10: TOTAL EXPENSES | D10: {=D113} -> 13441.7 | E10: {=E113} -> 9888.9 | F10: {=F113} -> 16814.8 | G10: {=G113} -> 18128.1 | H10: {=H113} -> 13110 | I10: {=I113} -> 20072.6 | J10: {=J113} -> 0 | K10: {=K113} -> 0 | ... O10: {=O113} -> 0 | Q10: {=SUM(D10:O10)} -> 91456.1
B11: PROFIT / LOSS | D11: {=D9-D10} -> 5199.1 | E11: {=E9-E10} -> 2551.5 | F11: {=F9-F10} -> 5237.6 | G11: {=G9-G10} -> 7963.5 | H11: {=H9-H10} -> -476.8 | I11: {=I9-I10} -> 5321.8 | J11: {=J9-J10} -> 0 | K11: {=K9-K10} -> 0 | ... O11: {=O9-O10} -> 7408.68 | Q11: {=Q9-Q10} -> 40368.88
B13: Clients
C14: TREND | D14: JANUARY | E14: FEBRUARY | F14: MARCH | G14: APRIL | H14: MAY | I14: JUNE | J14: JULY | K14: AUGUST | L14: SEPTEMBER | M14: OCTOBER | N14: NOVEMBER | O14: DECEMBER | Q14: YTD
B15: Pack Essentiel | D15: 0 | E15: 0 | F15: 0 | G15: 0 | H15: 0 | I15: 0 | J15: 0 | K15: 0 | L15: 12 | M15: 49 | N15: 89 | O15: 132 | Q15: {=SUM(D15:O15)} -> 282
B16: Pack Avantage | D16: 0 | E16: 0 | F16: 0 | G16: 0 | H16: 0 | I16: 0 | J16: 0 | K16: 0 | L16: 4 | M16: 16 | N16: 51 | O16: 78 | Q16: {=SUM(D16:O16)} -> 149
B17: Pack Élite | D17: 0 | E17: 0 | F17: 0 | G17: 0 | H17: 0 | I17: 0 | J17: 0 | K17: 0 | L17: 0 | M17: 7 | N17: 21 | O17: 34 | Q17: {=SUM(D17:O17)} -> 62
B18: VM Clash Royal | D18: 23 | E18: 31 | F18: 12 | G18: 7 | H18: 4 | I18: 26 | J18: 0 | K18: 0 | L18: 0 | M18: 0 | N18: 0 | O18: 0 | Q18: {=SUM(D18:O18)} -> 103
B19: VM Call Of Duty | D19: 8 | E19: 4 | F19: 9 | G19: 13 | H19: 3 | I19: 7 | J19: 0 | K19: 0 | L19: 0 | M19: 0 | N19: 0 | O19: 0 | Q19: {=SUM(D19:O19)} -> 44
B20: VM Overwatch 2 | D20: 2 | E20: 1 | F20: 6 | G20: 4 | H20: 8 | I20: 11 | J20: 0 | K20: 0 | L20: 0 | M20: 0 | N20: 0 | O20: 0 | Q20: {=SUM(D20:O20)} -> 32
B21: TOTAUX | D21: {=SUM(D15,D17,D18,D16,D19,D20)} -> 33 | E21: {=SUM(E15,E17,E18,E16,E19,E20)} -> 36 | F21: {=SUM(F15,F17,F18,F16,F19,F20)} -> 27 | G21: {=SUM(G15,G17,G18,G16,G19,G20)} -> 24 | H21: {=SUM(H15,H17,H18,H16,H19,H20)} -> 15 | I21: {=SUM(I15,I17,I18,I16,I19,I20)} -> 44 | J21: {=SUM(J15,J17,J18,J16,J19,J20)} -> 0 | K21: {=SUM(K15,K17,K18,K16,K19,K20)} -> 0 | ... O21: {=SUM(O15,O17,O18,O16,O19,O20)} -> 244 | Q21: {=SUM(Q15,Q16,Q17,Q18,Q19,Q20)} -> 672
B23: Enter the amounts for each month below. YTD amounts, YTD tab, graph, and trend lines will populate automatically.
B24: REVENUE | C24: TREND | D24: JANUARY | E24: FEBRUARY | F24: MARCH | G24: APRIL | H24: MAY | I24: JUNE | J24: JULY | K24: AUGUST | L24: SEPTEMBER | M24: OCTOBER | N24: NOVEMBER | O24: DECEMBER | Q24: YTD
B25: Pack Essentiel | D25: {=SUM(19.99*D15)} -> 0 | E25: {=SUM(19.99*E15)} -> 0 | F25: {=SUM(19.99*F15)} -> 0 | G25: {=SUM(19.99*G15)} -> 0 | H25: {=SUM(19.99*H15)} -> 0 | I25: {=SUM(19.99*I15)} -> 0 | J25: {=SUM(19.99*J15)} -> 0 | K25: {=SUM(19.99*K15)} -> 0 | ... O25: {=SUM(19.99*O15)} -> 2638.68 | Q25: {=SUM(D25:O25)} -> 5637.18
B26: Pack Avantage | D26: {=SUM(35*D16)} -> 0 | E26: {=SUM(35*E16)} -> 0 | F26: {=SUM(35*F16)} -> 0 | G26: {=SUM(35*G16)} -> 0 | H26: {=SUM(35*H16)} -> 0 | I26: {=SUM(35*I16)} -> 0 | J26: {=SUM(35*J16)} -> 0 | K26: {=SUM(35*K16)} -> 0 | ... O26: {=SUM(35*O16)} -> 2730 | Q26: {=SUM(D26:O26)} -> 5215
B27: Pack Élite | D27: {=SUM(60*D17)} -> 0 | E27: {=SUM(60*E17)} -> 0 | F27: {=SUM(60*F17)} -> 0 | G27: {=SUM(60*G17)} -> 0 | H27: {=SUM(60*H17)} -> 0 | I27: {=SUM(60*I17)} -> 0 | J27: {=SUM(60*J17)} -> 0 | K27: {=SUM(60*K17)} -> 0 | ... O27: {=SUM(60*O17)} -> 2040 | Q27: {=SUM(D27:O27)} -> 3720
B28: VM Clash Royal | D28: {=SUM(160*D18)} -> 3680 | E28: {=SUM(160*E18)} -> 4960 | F28: {=SUM(160*F18)} -> 1920 | G28: {=SUM(160*G18)} -> 1120 | H28: {=SUM(160*H18)} -> 640 | I28: {=SUM(160*I18)} -> 4160 | J28: {=SUM(160*J18)} -> 0 | K28: {=SUM(160*K18)} -> 0 | ... O28: {=SUM(160*O18)} -> 0 | Q28: {=SUM(D28:O28)} -> 16480
B29: VM Call Of Duty | D29: {=SUM(1650*D19)} -> 13200 | E29: {=SUM(1650*E19)} -> 6600 | F29: {=SUM(1650*F19)} -> 14850 | G29: {=SUM(1650*G19)} -> 21450 | H29: {=SUM(1650*H19)} -> 4950 | I29: {=SUM(1650*I19)} -> 11550 | J29: {=SUM(1650*J19)} -> 0 | K29: {=SUM(1650*K19)} -> 0 | ... O29: {=SUM(1650*O19)} -> 0 | Q29: {=SUM(D29:O29)} -> 72600
B30: VM Overwatch 2 | D30: {=SUM(880.4*D20)} -> 1760.8 | E30: {=SUM(880.4*E20)} -> 880.4 | F30: {=SUM(880.4*F20)} -> 5282.4 | G30: {=SUM(880.4*G20)} -> 3521.6 | H30: {=SUM(880.4*H20)} -> 7043.2 | I30: {=SUM(880.4*I20)} -> 9684.4 | J30: {=SUM(880.4*J20)} -> 0 | K30: {=SUM(880.4*K20)} -> 0 | ... O30: {=SUM(880.4*O20)} -> 0 | Q30: {=SUM(D30:O30)} -> 28172.8
B31: TOTAL REVENUE | D31: {=SUM(D25:D30)} -> 18640.8 | E31: {=SUM(E25:E30)} -> 12440.4 | F31: {=SUM(F25:F30)} -> 22052.4 | G31: {=SUM(G25:G30)} -> 26091.6 | H31: {=SUM(H25:H30)} -> 12633.2 | I31: {=SUM(I25:I30)} -> 25394.4 | J31: {=SUM(J25:J30)} -> 0 | K31: {=SUM(K25:K30)} -> 0 | ... O31: {=SUM(O25:O30)} -> 7408.68 | Q31: {=SUM(Q25:Q30)} -> 131824.98
B33: REDUCTIONS | C33: TREND | D33: JANUARY | E33: FEBRUARY | F33: MARCH | G33: APRIL | H33: MAY | I33: JUNE | J33: JULY | K33: AUGUST | L33: SEPTEMBER | M33: OCTOBER | N33: NOVEMBER | O33: DECEMBER | Q33: YTD
B34: Less Sales Returns | D34: 0 | E34: 0 | F34: 0 | G34: 0 | H34: 0 | I34: 0 | J34: 0 | K34: 0 | L34: 0 | M34: 0 | N34: 0 | O34: 0 | Q34: {=SUM(D34:O34)} -> 0
B35: Less Sales Discounts | D35: 0 | E35: 0 | F35: 0 | G35: 0 | H35: 0 | I35: 0 | J35: 0 | K35: 0 | L35: 0 | M35: 0 | N35: 0 | O35: 0 | Q35: {=SUM(D35:O35)} -> 0
B36: Less Cost of Goods Sold | D36: 0 | E36: 0 | F36: 0 | G36: 0 | H36: 0 | I36: 0 | J36: 0 | K36: 0 | L36: 0 | M36: 0 | N36: 0 | O36: 0 | Q36: {=SUM(D36:O36)} -> 0
B37: TOTAL REDUCTIONS | D37: {=SUM(D34:D36)} -> 0 | E37: {=SUM(E34:E36)} -> 0 | F37: {=SUM(F34:F36)} -> 0 | G37: {=SUM(G34:G36)} -> 0 | H37: {=SUM(H34:H36)} -> 0 | I37: {=SUM(I34:I36)} -> 0 | J37: {=SUM(J34:J36)} -> 0 | K37: {=SUM(K34:K36)} -> 0 | ... O37: {=SUM(O34:O36)} -> 0 | Q37: {=SUM(Q34:Q36)} -> 0
B39: GROSS PROFIT | SALES MINUS REDUCTIONS | D39: {=D31-D37} -> 18640.8 | E39: {=E31-E37} -> 12440.4 | F39: {=F31-F37} -> 22052.4 | G39: {=G31-G37} -> 26091.6 | H39: {=H31-H37} -> 12633.2 | I39: {=I31-I37} -> 25394.4 | J39: {=J31-J37} -> 0 | K39: {=K31-K37} -> 0 | ... O39: {=O31-O37} -> 7408.68 | Q39: {=Q31-Q37} -> 131824.98
B41: EXPENSES
B42: EMPLOYEE | C42: TREND | D42: JANUARY | E42: FEBRUARY | F42: MARCH | G42: APRIL | H42: MAY | I42: JUNE | J42: JULY | K42: AUGUST | L42: SEPTEMBER | M42: OCTOBER | N42: NOVEMBER | O42: DECEMBER | Q42: YTD
B43: Luf | C43: Freelance | D43: 4000 | E43: 4000 | F43: 4000 | G43: 4000 | H43: 4000 | I43: 4000 | J43: 0 | K43: 0 | L43: 0 | M43: 0 | N43: 0 | O43: 0 | Q43: {=SUM(D43:O43)} -> 24000
B44: Gengis | D44: 0 | E44: 0 | F44: 0 | G44: 0 | H44: 0 | I44: 0 | J44: 0 | K44: 0 | L44: 0 | M44: 0 | N44: 0 | O44: 0 | Q44: {=SUM(D44:O44)} -> 0
B45: Other | D45: 0 | E45: 0 | F45: 0 | G45: 0 | H45: 0 | I45: 0 | J45: 0 | K45: 0 | L45: 0 | M45: 0 | N45: 0 | O45: 0 | Q45: {=SUM(D45:O45)} -> 0
B46: Other | D46: 0 | E46: 0 | F46: 0 | G46: 0 | H46: 0 | I46: 0 | J46: 0 | K46: 0 | L46: 0 | M46: 0 | N46: 0 | O46: 0 | Q46: {=SUM(D46:O46)} -> 0
B47: Other | D47: 0 | E47: 0 | F47: 0 | G47: 0 | H47: 0 | I47: 0 | J47: 0 | K47: 0 | L47: 0 | M47: 0 | N47: 0 | O47: 0 | Q47: {=SUM(D47:O47)} -> 0
...

Sheet SAMPLE - Monthly Profit & Loss-
B1: MONTHLY PROFIT AND LOSS
B2: COMPANY NAME
B3: FormaCash
B5: Last Update and verification
B6: 45473
C8: TREND | D8: JANUARY | E8: FEBRUARY | F8: MARCH | G8: APRIL | H8: MAY | I8: JUNE | J8: JULY | K8: AUGUST | L8: SEPTEMBER | M8: OCTOBER | N8: NOVEMBER | O8: DECEMBER | Q8: YTD
B9: GROSS PROFIT | D9: {=D37} -> 2500 | E9: {=E37} -> 70500 | F9: {=F37} -> 46500 | G9: {=G37} -> 76500 | H9: {=H37} -> 104500 | I9: {=I37} -> 83500 | J9: {=J37} -> 96500 | K9: {=K37} -> 66000 | ... O9: {=O37} -> 0 | Q9: {=SUM(D9:O9)} -> 806000
B10: TOTAL EXPENSES | D10: {=D111} -> 166 | E10: {=E111} -> 37506 | F10: {=F111} -> 45500.98 | G10: {=G111} -> 55631.5 | H10: {=H111} -> 72766 | I10: {=I111} -> 59296 | J10: {=J111} -> 57826 | K10: {=K111} -> 42756 | ... O10: {=O111} -> 0 | Q10: {=SUM(D10:O10)} -> 547276.48
B11: PROFIT / LOSS | D11: {=D9-D10} -> 2334 | E11: {=E9-E10} -> 32994 | F11: {=F9-F10} -> 999.02 | G11: {=G9-G10} -> 20868.5 | H11: {=H9-H10} -> 31734 | I11: {=I9-I10} -> 24204 | J11: {=J9-J10} -> 38674 | K11: {=K9-K10} -> 23244 | ... O11: {=O9-O10} -> 0 | Q11: {=Q9-Q10} -> 258723.52
B13: Clients
C14: TREND | D14: JANUARY | E14: FEBRUARY | F14: MARCH | G14: APRIL | H14: MAY | I14: JUNE | J14: JULY | K14: AUGUST | L14: SEPTEMBER | M14: OCTOBER | N14: NOVEMBER | O14: DECEMBER | Q14: YTD
B15: Développement web | D15: 0 | E15: 14 | F15: 8 | G15: 12 | H15: 16 | I15: 13 | J15: 17 | K15: 13 | L15: 14 | M15: 20 | N15: 7 | Q15: {=SUM(D15:O15)} -> 134
B16: No-Code | D16: 1 | E16: 3 | F16: 6 | G16: 9 | H16: 13 | I16: 10 | J16: 8 | K16: 3 | L16: 16 | M16: 8 | N16: 6 | Q16: {=SUM(D16:O16)} -> 83
B17: TOTAUX | D17: {=SUM(D15,D16)} -> 1 | E17: {=SUM(E15,E16)} -> 17 | F17: {=SUM(F15,F16)} -> 14 | G17: {=SUM(G15,G16)} -> 21 | H17: {=SUM(H15,H16)} -> 29 | I17: {=SUM(I15,I16)} -> 23 | J17: {=SUM(J15,J16)} -> 25 | K17: {=SUM(K15,K16)} -> 16 | ... O17: {=SUM(O15,O16)} -> 0 | Q17: {=SUM(Q15,Q16)} -> 217
B19: Enter the amounts for each month below. YTD amounts, YTD tab, graph, and trend lines will populate automatically.
B20: REVENUE | C20: TREND | D20: JANUARY | E20: FEBRUARY | F20: MARCH | G20: APRIL | H20: MAY | I20: JUNE | J20: JULY | K20: AUGUST | L20: SEPTEMBER | M20: OCTOBER | N20: NOVEMBER | O20: DECEMBER | Q20: YTD
B21: Développement Web et Mobile | D21: {=SUM(4500*D15)} -> 0 | E21: {=SUM(4500*E15)} -> 63000 | F21: {=SUM(4500*F15)} -> 36000 | G21: {=SUM(4500*G15)} -> 54000 | H21: {=SUM(4500*H15)} -> 72000 | I21: {=SUM(4500*I15)} -> 58500 | J21: {=SUM(4500*J15)} -> 76500 | K21: {=SUM(4500*K15)} -> 58500 | ... O21: {=SUM(4500*O15)} -> 0 | Q21: {=SUM(D21:O21)} -> 603000
B22: No Code | D22: {=SUM(2500*D16)} -> 2500 | E22: {=SUM(2500*E16)} -> 7500 | F22: {=SUM(2500*F16)} -> 15000 | G22: {=SUM(2500*G16)} -> 22500 | H22: {=SUM(2500*H16)} -> 32500 | I22: {=SUM(2500*I16)} -> 25000 | J22: {=SUM(2500*J16)} -> 20000 | K22: {=SUM(2500*K16)} -> 7500 | ... O22: {=SUM(2500*O16)} -> 0 | Q22: {=SUM(D22:O22)} -> 207500
B23: Other Income 3 | D23: 0 | E23: 0 | F23: 0 | G23: 0 | H23: 0 | I23: 0 | J23: 0 | K23: 0 | L23: 0 | M23: 0 | N23: 0 | O23: 0 | Q23: {=SUM(D23:O23)} -> 0
B24: Other Income 4 | D24: 0 | E24: 0 | F24: 0 | G24: 0 | H24: 0 | I24: 0 | J24: 0 | K24: 0 | L24: 0 | M24: 0 | N24: 0 | O24: 0 | Q24: {=SUM(D24:O24)} -> 0
B25: Other Income 5 | D25: 0 | E25: 0 | F25: 0 | G25: 0 | H25: 0 | I25: 0 | J25: 0 | K25: 0 | L25: 0 | M25: 0 | N25: 0 | O25: 0 | Q25: {=SUM(D25:O25)} -> 0
B26: Other Income 6 | D26: 0 | E26: 0 | F26: 0 | G26: 0 | H26: 0 | I26: 0 | J26: 0 | K26: 0 | L26: 0 | M26: 0 | N26: 0 | O26: 0 | Q26: {=SUM(D26:O26)} -> 0
B27: Other Income 7 | D27: 0 | E27: 0 | F27: 0 | G27: 0 | H27: 0 | I27: 0 | J27: 0 | K27: 0 | L27: 0 | M27: 0 | N27: 0 | O27: 0 | Q27: {=SUM(D27:O27)} -> 0
B28: Other Income 8 | D28: 0 | E28: 0 | F28: 0 | G28: 0 | H28: 0 | I28: 0 | J28: 0 | K28: 0 | L28: 0 | M28: 0 | N28: 0 | O28: 0 | Q28: {=SUM(D28:O28)} -> 0
B29: TOTAL REVENUE | D29: {=SUM(D21:D28)} -> 2500 | E29: {=SUM(E21:E28)} -> 70500 | F29: {=SUM(F21:F28)} -> 51000 | G29: {=SUM(G21:G28)} -> 76500 | H29: {=SUM(H21:H28)} -> 104500 | I29: {=SUM(I21:I28)} -> 83500 | J29: {=SUM(J21:J28)} -> 96500 | K29: {=SUM(K21:K28)} -> 66000 | ... O29: {=SUM(O21:O28)} -> 0 | Q29: {=SUM(Q21:Q28)} -> 810500
B31: REDUCTIONS | C31: TREND | D31: JANUARY | E31: FEBRUARY | F31: MARCH | G31: APRIL | H31: MAY | I31: JUNE | J31: JULY | K31: AUGUST | L31: SEPTEMBER | M31: OCTOBER | N31: NOVEMBER | O31: DECEMBER | Q31: YTD
B32: Less Sales Returns | D32: 0 | E32: 0 | F32: 4500 | G32: 0 | H32: 0 | I32: 0 | J32: 0 | K32: 0 | L32: 0 | M32: 0 | N32: 0 | O32: 0 | Q32: {=SUM(D32:O32)} -> 4500
B33: Less Sales Discounts | D33: 0 | E33: 0 | F33: 0 | G33: 0 | H33: 0 | I33: 0 | J33: 0 | K33: 0 | L33: 0 | M33: 0 | N33: 0 | O33: 0 | Q33: {=SUM(D33:O33)} -> 0
B34: Less Cost of Goods Sold | D34: 0 | E34: 0 | F34: 0 | G34: 0 | H34: 0 | I34: 0 | J34: 0 | K34: 0 | L34: 0 | M34: 0 | N34: 0 | O34: 0 | Q34: {=SUM(D34:O34)} -> 0
B35: TOTAL REDUCTIONS | D35: {=SUM(D32:D34)} -> 0 | E35: {=SUM(E32:E34)} -> 0 | F35: {=SUM(F32:F34)} -> 4500 | G35: {=SUM(G32:G34)} -> 0 | H35: {=SUM(H32:H34)} -> 0 | I35: {=SUM(I32:I34)} -> 0 | J35: {=SUM(J32:J34)} -> 0 | K35: {=SUM(K32:K34)} -> 0 | ... O35: {=SUM(O32:O34)} -> 0 | Q35: {=SUM(Q32:Q34)} -> 4500
B37: GROSS PROFIT | SALES MINUS REDUCTIONS | D37: {=D29-D35} -> 2500 | E37: {=E29-E35} -> 70500 | F37: {=F29-F35} -> 46500 | G37: {=G29-G35} -> 76500 | H37: {=H29-H35} -> 104500 | I37: {=I29-I35} -> 83500 | J37: {=J29-J35} -> 96500 | K37: {=K29-K35} -> 66000 | ... O37: {=O29-O35} -> 0 | Q37: {=Q29-Q35} -> 806000
B39: EXPENSES
B40: EMPLOYEE | C40: TREND | D40: JANUARY | E40: FEBRUARY | F40: MARCH | G40: APRIL | H40: MAY | I40: JUNE | J40: JULY | K40: AUGUST | L40: SEPTEMBER | M40: OCTOBER | N40: NOVEMBER | O40: DECEMBER | Q40: YTD
B41: Josselin MORELLE | C41: Développement web | D41: 0 | E41: 0 | F41: 800 | G41: 2000 | H41: 3450 | I41: 4200 | J41: 4890 | K41: 5300 | L41: 5800 | M41: 2000 | N41: 1300 | O41: 0 | Q41: {=SUM(D41:O41)} -> 29740
B42: Zahra GUERBI | C42: Développement web | D42: 0 | E42: 0 | F42: 0 | G42: 0 | H42: 0 | I42: 0 | J42: 0 | K42: 0 | L42: 0 | M42: 0 | N42: 0 | O42: 0 | Q42: {=SUM(D42:O42)} -> 0
B43: Gaylor LOCHE | C43: Freelance | D43: 0 | E43: 4000 | F43: 4000 | G43: 0 | H43: 0 | I43: 0 | J43: 0 | K43: 0 | L43: 0 | M43: 0 | N43: 0 | O43: 0 | Q43: {=SUM(D43:O43)} -> 8000
B44: Christophe Badidou | C44: Développement web | D44: 0 | E44: 11200 | F44: 11200 | G44: 11200 | H44: 0 | I44: 0 | J44: 0 | K44: 0 | L44: 0 | M44: 0 | N44: 0 | O44: 0 | Q44: {=SUM(D44:O44)} -> 33600
B45: Emmanuel Gutman | C45: Freelance | D45: 0 | E45: 4500 | F45: 4500 | G45: 4500 | H45: 4500 | I45: 0 | J45: 0 | K45: 0 | L45: 0 | M45: 0 | N45: 0 | O45: 0 | Q45: {=SUM(D45:O45)} -> 18000
B46: Séverine Pereira | C46: Développement web | D46: 0 | E46: 0 | F46: 0 | G46: 2400 | H46: 1630 | I46: 1630 | J46: 1630 | K46: 1630 | L46: 1630 | M46: 1630 | N46: 1630 | O46: 0 | Q46: {=SUM(D46:O46)} -> 13810
B47: Tom Charmasson | C47: Développement web | D47: 0 | E47: 0 | F47: 0 | G47: 0 | H47: 2450 | I47: 2450 | J47: 2450 | K47: 2450 | L47: 2450 | M47: 2450 | N47: 2450 | O47: 0 | Q47: {=SUM(D47:O47)} -> 17150
...

Sheet SAMPLE - Profit & Loss YTD - Ta
B1: SAMPLE PROFIT AND LOSS YTD
B2: COMPANY NAME
B3: {='SAMPLE - Monthly Profit & Loss '!B3} -> Hackboot
B5: Last Update and verification
B6: {='SAMPLE - Monthly Profit & Loss '!B6} -> 45984
C8: YTD
B9: GROSS PROFIT | C9: {='SAMPLE - Monthly Profit & Loss '!Q9} -> 131824.98
B10: TOTAL EXPENSES | C10: {='SAMPLE - Monthly Profit & Loss '!Q10} -> 91456.1
B11: PROFIT / LOSS | C11: {='SAMPLE - Monthly Profit & Loss '!Q11} -> 40368.88
B13: REVENUE | C13: {='SAMPLE - Monthly Profit & Loss '!Q24} -> YTD
B14: {='SAMPLE - Monthly Profit & Loss '!B25} -> Pack Essentiel | C14: {='SAMPLE - Monthly Profit & Loss '!Q25} -> 5637.18
B15: {='SAMPLE - Monthly Profit & Loss '!B26} -> Pack Avantage | C15: {='SAMPLE - Monthly Profit & Loss '!Q26} -> 5215
B16: {='SAMPLE - Monthly Profit & Loss '!B27} -> Pack Élite | C16: {='SAMPLE - Monthly Profit & Loss '!Q27} -> 3720
B17: {='SAMPLE - Monthly Profit & Loss '!B28} -> VM Clash Royal | C17: {='SAMPLE - Monthly Profit & Loss '!Q28} -> 16480
B18: {='SAMPLE - Monthly Profit & Loss '!B29} -> VM Call Of Duty | C18: {='SAMPLE - Monthly Profit & Loss '!Q29} -> 72600
B19: {='SAMPLE - Monthly Profit & Loss '!B30} -> VM Overwatch 2 | C19: {='SAMPLE - Monthly Profit & Loss '!Q30} -> 28172.8
B20: {=#REF!} | C20: {=#REF!}
B21: {=#REF!} | C21: {=#REF!}
B22: TOTAL REVENUE | C22: {='SAMPLE - Monthly Profit & Loss '!Q31} -> 131824.98
B24: REDUCTIONS | C24: {='SAMPLE - Monthly Profit & Loss '!Q33} -> YTD
B25: Less sales returns | C25: {='SAMPLE - Monthly Profit & Loss '!Q34} -> 0
B26: Less sales discounts | C26: {='SAMPLE - Monthly Profit & Loss '!Q35} -> 0
B27: Less cost of goods sold | C27: {='SAMPLE - Monthly Profit & Loss '!Q36} -> 0
B28: TOTAL REDUCTIONS | C28: {='SAMPLE - Monthly Profit & Loss '!Q37} -> 0
B30: GROSS PROFIT | SALES MINUS REDUCTIONS | C30: {='SAMPLE - Monthly Profit & Loss '!Q39} -> 131824.98
B32: EXPENSES
B33: EMPLOYEE AND LABOR | C33: {='SAMPLE - Monthly Profit & Loss '!Q42} -> YTD
B34: {='SAMPLE - Monthly Profit & Loss '!B43} -> Luf | C34: {='SAMPLE - Monthly Profit & Loss '!Q43} -> 24000
B35: {='SAMPLE - Monthly Profit & Loss '!B44} -> Gengis | C35: {='SAMPLE - Monthly Profit & Loss '!Q44} -> 0
B36: {='SAMPLE - Monthly Profit & Loss '!B45} -> Other | C36: {='SAMPLE - Monthly Profit & Loss '!Q45} -> 0
B37: {='SAMPLE - Monthly Profit & Loss '!B46} -> Other | C37: {='SAMPLE - Monthly Profit & Loss '!Q46} -> 0
B38: {='SAMPLE - Monthly Profit & Loss '!B47} -> Other | C38: {='SAMPLE - Monthly Profit & Loss '!Q47} -> 0
B39: {='SAMPLE - Monthly Profit & Loss '!B48} -> Other | C39: {='SAMPLE - Monthly Profit & Loss '!Q48} -> 0
B40: {='SAMPLE - Monthly Profit & Loss '!B49} -> Other | C40: {='SAMPLE - Monthly Profit & Loss '!Q49} -> 0
B41: {='SAMPLE - Monthly Profit & Loss '!B50} -> Other | C41: {='SAMPLE - Monthly Profit & Loss '!Q50} -> 0
B42: {='SAMPLE - Monthly Profit & Loss '!B51} -> Other | C42: {='SAMPLE - Monthly Profit & Loss '!Q51} -> 0
B43: {='SAMPLE - Monthly Profit & Loss '!B52} -> Other | C43: {='SAMPLE - Monthly Profit & Loss '!Q52} -> 0
B44: {='SAMPLE - Monthly Profit & Loss '!B53} -> Other | C44: {='SAMPLE - Monthly Profit & Loss '!Q53} -> 0
B45: {='SAMPLE - Monthly Profit & Loss '!B54} -> Other | C45: {='SAMPLE - Monthly Profit & Loss '!Q54} -> 0
... B48: {='SAMPLE - Monthly Profit & Loss '!B57} -> Other | C48: {='SAMPLE - Monthly Profit & Loss '!Q57} -> 0
...

Sheet BLANK - Monthly Profit & Loss -
B1: MONTHLY PROFIT AND LOSS TEMPLATE
B2: COMPANY NAME
B5: TIME PERIOD REPRESENTED
C8: TREND | D8: JANUARY | E8: FEBRUARY | F8: MARCH | G8: APRIL | H8: MAY | I8: JUNE | J8: JULY | K8: AUGUST | L8: SEPTEMBER | M8: OCTOBER | N8: NOVEMBER | O8: DECEMBER | Q8: YTD
B9: GROSS PROFIT | D9: {=D31} -> 0 | E9: {=E31} -> 0 | F9: {=F31} -> 0 | G9: {=G31} -> 0 | H9: {=H31} -> 0 | I9: {=I31} -> 0 | J9: {=J31} -> 0 | K9: {=K31} -> 0 | ... O9: {=O31} -> 0 | Q9: {=SUM(D9:O9)} -> 0
B10: TOTAL EXPENSES | D10: {=D99} -> 0 | E10: {=E99} -> 0 | F10: {=F99} -> 0 | G10: {=G99} -> 0 | H10: {=H99} -> 0 | I10: {=I99} -> 0 | J10: {=J99} -> 0 | K10: {=K99} -> 0 | ... O10: {=O99} -> 0 | Q10: {=SUM(D10:O10)} -> 0
B11: PROFIT / LOSS | D11: {=D9-D10} -> 0 | E11: {=E9-E10} -> 0 | F11: {=F9-F10} -> 0 | G11: {=G9-G10} -> 0 | H11: {=H9-H10} -> 0 | I11: {=I9-I10} -> 0 | J11: {=J9-J10} -> 0 | K11: {=K9-K10} -> 0 | ... O11: {=O9-O10} -> 0 | Q11: {=Q9-Q10} -> 0
B13: Enter the amounts for each month below. YTD amounts, YTD tab, graph, and trend lines will populate automatically.
B14: REVENUE | C14: TREND | D14: JANUARY | E14: FEBRUARY | F14: MARCH | G14: APRIL | H14: MAY | I14: JUNE | J14: JULY | K14: AUGUST | L14: SEPTEMBER | M14: OCTOBER | N14: NOVEMBER | O14: DECEMBER | Q14: YTD
B15: Income from Sales | D15: 0 | E15: 0 | F15: 0 | G15: 0 | H15: 0 | I15: 0 | J15: 0 | K15: 0 | L15: 0 | M15: 0 | N15: 0 | O15: 0 | Q15: {=SUM(D15:O15)} -> 0
B16: Adjustments to Earnings | D16: 0 | E16: 0 | F16: 0 | G16: 0 | H16: 0 | I16: 0 | J16: 0 | K16: 0 | L16: 0 | M16: 0 | N16: 0 | O16: 0 | Q16: {=SUM(D16:O16)} -> 0
B17: Sales of Assets | D17: 0 | E17: 0 | F17: 0 | G17: 0 | H17: 0 | I17: 0 | J17: 0 | K17: 0 | L17: 0 | M17: 0 | N17: 0 | O17: 0 | Q17: {=SUM(D17:O17)} -> 0
B18: Gains from Legal Actions | D18: 0 | E18: 0 | F18: 0 | G18: 0 | H18: 0 | I18: 0 | J18: 0 | K18: 0 | L18: 0 | M18: 0 | N18: 0 | O18: 0 | Q18: {=SUM(D18:O18)} -> 0
B19: Interest Received | D19: 0 | E19: 0 | F19: 0 | G19: 0 | H19: 0 | I19: 0 | J19: 0 | K19: 0 | L19: 0 | M19: 0 | N19: 0 | O19: 0 | Q19: {=SUM(D19:O19)} -> 0
B20: Other Income 1 | D20: 0 | E20: 0 | F20: 0 | G20: 0 | H20: 0 | I20: 0 | J20: 0 | K20: 0 | L20: 0 | M20: 0 | N20: 0 | O20: 0 | Q20: {=SUM(D20:O20)} -> 0
B21: Other Income 2 | D21: 0 | E21: 0 | F21: 0 | G21: 0 | H21: 0 | I21: 0 | J21: 0 | K21: 0 | L21: 0 | M21: 0 | N21: 0 | O21: 0 | Q21: {=SUM(D21:O21)} -> 0
B22: Other Income 3 | D22: 0 | E22: 0 | F22: 0 | G22: 0 | H22: 0 | I22: 0 | J22: 0 | K22: 0 | L22: 0 | M22: 0 | N22: 0 | O22: 0 | Q22: {=SUM(D22:O22)} -> 0
B23: TOTAL REVENUE | D23: {=SUM(D15:D22)} -> 0 | E23: {=SUM(E15:E22)} -> 0 | F23: {=SUM(F15:F22)} -> 0 | G23: {=SUM(G15:G22)} -> 0 | H23: {=SUM(H15:H22)} -> 0 | I23: {=SUM(I15:I22)} -> 0 | J23: {=SUM(J15:J22)} -> 0 | K23: {=SUM(K15:K22)} -> 0 | ... O23: {=SUM(O15:O22)} -> 0 | Q23: {=SUM(Q15:Q22)} -> 0
B25: REDUCTIONS | C25: TREND | D25: JANUARY | E25: FEBRUARY | F25: MARCH | G25: APRIL | H25: MAY | I25: JUNE | J25: JULY | K25: AUGUST | L25: SEPTEMBER | M25: OCTOBER | N25: NOVEMBER | O25: DECEMBER | Q25: YTD
B26: Less Sales Returns | D26: 0 | E26: 0 | F26: 0 | G26: 0 | H26: 0 | I26: 0 | J26: 0 | K26: 0 | L26: 0 | M26: 0 | N26: 0 | O26: 0 | Q26: {=SUM(D26:O26)} -> 0
B27: Less Sales Discounts | D27: 0 | E27: 0 | F27: 0 | G27: 0 | H27: 0 | I27: 0 | J27: 0 | K27: 0 | L27: 0 | M27: 0 | N27: 0 | O27: 0 | Q27: {=SUM(D27:O27)} -> 0
B28: Less Cost of Goods Sold | D28: 0 | E28: 0 | F28: 0 | G28: 0 | H28: 0 | I28: 0 | J28: 0 | K28: 0 | L28: 0 | M28: 0 | N28: 0 | O28: 0 | Q28: {=SUM(D28:O28)} -> 0
B29: TOTAL REDUCTIONS | D29: {=SUM(D26:D28)} -> 0 | E29: {=SUM(E26:E28)} -> 0 | F29: {=SUM(F26:F28)} -> 0 | G29: {=SUM(G26:G28)} -> 0 | H29: {=SUM(H26:H28)} -> 0 | I29: {=SUM(I26:I28)} -> 0 | J29: {=SUM(J26:J28)} -> 0 | K29: {=SUM(K26:K28)} -> 0 | ... O29: {=SUM(O26:O28)} -> 0 | Q29: {=SUM(Q26:Q28)} -> 0
B31: GROSS PROFIT | SALES MINUS REDUCTIONS | D31: {=D23-D29} -> 0 | E31: {=E23-E29} -> 0 | F31: {=F23-F29} -> 0 | G31: {=G23-G29} -> 0 | H31: {=H23-H29} -> 0 | I31: {=I23-I29} -> 0 | J31: {=J23-J29} -> 0 | K31: {=K23-K29} -> 0 | ... O31: {=O23-O29} -> 0 | Q31: {=Q23-Q29} -> 0
B33: EXPENSES
B34: EMPLOYEE AND LABOR | C34: TREND | D34: JANUARY | E34: FEBRUARY | F34: MARCH | G34: APRIL | H34: MAY | I34: JUNE | J34: JULY | K34: AUGUST | L34: SEPTEMBER | M34: OCTOBER | N34: NOVEMBER | O34: DECEMBER | Q34: YTD
B35: Salaries | D35: 0 | E35: 0 | F35: 0 | G35: 0 | H35: 0 | I35: 0 | J35: 0 | K35: 0 | L35: 0 | M35: 0 | N35: 0 | O35: 0 | Q35: {=SUM(D35:O35)} -> 0
B36: Wages | D36: 0 | E36: 0 | F36: 0 | G36: 0 | H36: 0 | I36: 0 | J36: 0 | K36: 0 | L36: 0 | M36: 0 | N36: 0 | O36: 0 | Q36: {=SUM(D36:O36)} -> 0
B37: Benefits | D37: 0 | E37: 0 | F37: 0 | G37: 0 | H37: 0 | I37: 0 | J37: 0 | K37: 0 | L37: 0 | M37: 0 | N37: 0 | O37: 0 | Q37: {=SUM(D37:O37)} -> 0
B38: Pension/Retirement | D38: 0 | E38: 0 | F38: 0 | G38: 0 | H38: 0 | I38: 0 | J38: 0 | K38: 0 | L38: 0 | M38: 0 | N38: 0 | O38: 0 | Q38: {=SUM(D38:O38)} -> 0
B39: Commissions | D39: 0 | E39: 0 | F39: 0 | G39: 0 | H39: 0 | I39: 0 | J39: 0 | K39: 0 | L39: 0 | M39: 0 | N39: 0 | O39: 0 | Q39: {=SUM(D39:O39)} -> 0
B40: Workers Comp | D40: 0 | E40: 0 | F40: 0 | G40: 0 | H40: 0 | I40: 0 | J40: 0 | K40: 0 | L40: 0 | M40: 0 | N40: 0 | O40: 0 | Q40: {=SUM(D40:O40)} -> 0
B41: Contract Labor | D41: 0 | E41: 0 | F41: 0 | G41: 0 | H41: 0 | I41: 0 | J41: 0 | K41: 0 | L41: 0 | M41: 0 | N41: 0 | O41: 0 | Q41: {=SUM(D41:O41)} -> 0
B42: Training | D42: 0 | E42: 0 | F42: 0 | G42: 0 | H42: 0 | I42: 0 | J42: 0 | K42: 0 | L42: 0 | M42: 0 | N42: 0 | O42: 0 | Q42: {=SUM(D42:O42)} -> 0
B43: Other | D43: 0 | E43: 0 | F43: 0 | G43: 0 | H43: 0 | I43: 0 | J43: 0 | K43: 0 | L43: 0 | M43: 0 | N43: 0 | O43: 0 | Q43: {=SUM(D43:O43)} -> 0
B44: TOTAL EMPLOYEE AND LABOR EXPENSE | D44: {=SUM(D35:D43)} -> 0 | E44: {=SUM(E35:E43)} -> 0 | F44: {=SUM(F35:F43)} -> 0 | G44: {=SUM(G35:G43)} -> 0 | H44: {=SUM(H35:H43)} -> 0 | I44: {=SUM(I35:I43)} -> 0 | J44: {=SUM(J35:J43)} -> 0 | K44: {=SUM(K35:K43)} -> 0 | ... O44: {=SUM(O35:O43)} -> 0 | Q44: {=SUM(Q35:Q43)} -> 0
B46: PROFESSIONAL SERVICES | C46: TREND | D46: JANUARY | E46: FEBRUARY | F46: MARCH | G46: APRIL | H46: MAY | I46: JUNE | J46: JULY | K46: AUGUST | L46: SEPTEMBER | M46: OCTOBER | N46: NOVEMBER | O46: DECEMBER | Q46: YTD
B47: Outside Services | D47: 0 | E47: 0 | F47: 0 | G47: 0 | H47: 0 | I47: 0 | J47: 0 | K47: 0 | L47: 0 | M47: 0 | N47: 0 | O47: 0 | Q47: {=SUM(D47:O47)} -> 0
B48: Accounting | D48: 0 | E48: 0 | F48: 0 | G48: 0 | H48: 0 | I48: 0 | J48: 0 | K48: 0 | L48: 0 | M48: 0 | N48: 0 | O48: 0 | Q48: {=SUM(D48:O48)} -> 0
B49: Legal | D49: 0 | E49: 0 | F49: 0 | G49: 0 | H49: 0 | I49: 0 | J49: 0 | K49: 0 | L49: 0 | M49: 0 | N49: 0 | O49: 0 | Q49: {=SUM(D49:O49)} -> 0
...

Sheet BLANK - Profit & Loss YTD - Tab
B1: SAMPLE PROFIT AND LOSS YTD | E1: Data on this tab will populate automatically.
B2: COMPANY NAME
B3: {='BLANK - Monthly Profit & Loss -'!B3} -> 0
B5: TIME PERIOD REPRESENTED
B6: {='BLANK - Monthly Profit & Loss -'!B6} -> 0
C8: YTD
B9: GROSS PROFIT | C9: {='BLANK - Monthly Profit & Loss -'!Q9} -> 0
B10: TOTAL EXPENSES | C10: {='BLANK - Monthly Profit & Loss -'!Q10} -> 0
B11: PROFIT / LOSS | C11: {='BLANK - Monthly Profit & Loss -'!Q11} -> 0
B13: REVENUE | C13: {='BLANK - Monthly Profit & Loss -'!Q14} -> YTD
B14: Income from sales | C14: {='BLANK - Monthly Profit & Loss -'!Q15} -> 0
B15: Adjustments to earnings | C15: {='BLANK - Monthly Profit & Loss -'!Q16} -> 0
B16: Sales of assets | C16: {='BLANK - Monthly Profit & Loss -'!Q17} -> 0
B17: Gains from legal actions | C17: {='BLANK - Monthly Profit & Loss -'!Q18} -> 0
B18: Interest received | C18: {='BLANK - Monthly Profit & Loss -'!Q19} -> 0
B19: Other income 1 | C19: {='BLANK - Monthly Profit & Loss -'!Q20} -> 0
B20: Other income 2 | C20: {='BLANK - Monthly Profit & Loss -'!Q21} -> 0
B21: Other income 3 | C21: {='BLANK - Monthly Profit & Loss -'!Q22} -> 0
B22: TOTAL REVENUE | C22: {='BLANK - Monthly Profit & Loss -'!Q23} -> 0
B24: REDUCTIONS | C24: {='BLANK - Monthly Profit & Loss -'!Q25} -> YTD
B25: Less sales returns | C25: {='BLANK - Monthly Profit & Loss -'!Q26} -> 0
... B30: GROSS PROFIT | SALES MINUS REDUCTIONS | C30: {='BLANK - Monthly Profit & Loss -'!Q31} -> 0
B32: EXPENSES
B33: EMPLOYEE AND LABOR | C33: {='BLANK - Monthly Profit & Loss -'!Q34} -> YTD
B34: Salaries | C34: {='BLANK - Monthly Profit & Loss -'!Q35} -> 0
B35: Wages | C35: {='BLANK - Monthly Profit & Loss -'!Q36} -> 0
B36: Benefits | C36: {='BLANK - Monthly Profit & Loss -'!Q37} -> 0
B37: Pension/retirement | C37: {='BLANK - Monthly Profit & Loss -'!Q38} -> 0
B38: Commissions | C38: {='BLANK - Monthly Profit & Loss -'!Q39} -> 0
B39: Workers comp | C39: {='BLANK - Monthly Profit & Loss -'!Q40} -> 0
B40: Contract labor | C40: {='BLANK - Monthly Profit & Loss -'!Q41} -> 0
B41: Training | C41: {='BLANK - Monthly Profit & Loss -'!Q42} -> 0
B42: Other | C42: {='BLANK - Monthly Profit & Loss -'!Q43} -> 0
B43: TOTAL EMPLOYEE AND LABOR EXPENSE | C43: {='BLANK - Monthly Profit & Loss -'!Q44} -> 0
B45: PROFESSIONAL SERVICES | C45: {='BLANK - Monthly Profit & Loss -'!Q46} -> YTD
... B50: Other | C50: {='BLANK - Monthly Profit & Loss -'!Q51} -> 0
C51: {='BLANK - Monthly Profit & Loss -'!Q52} -> 0
B53: BANKING AND FINANCE | C53: {='BLANK - Monthly Profit & Loss -'!Q54} -> YTD
B54: Bank fees | C54: {='BLANK - Monthly Profit & Loss -'!Q55} -> 0
B55: Bad debts | C55: {='BLANK - Monthly Profit & Loss -'!Q56} -> 0
...
